Traceback (most recent call last):
  File "C:\Users\adnegrau\AppData\Local\Programs\Python\Python312\Lib\site-packages\jupyter_cache\executors\utils.py", line 58, in single_nb_execution
    executenb(
  File "C:\Users\adnegrau\AppData\Local\Programs\Python\Python312\Lib\site-packages\nbclient\client.py", line 1305, in execute
    return NotebookClient(nb=nb, resources=resources, km=km, **kwargs).execute()
           ^^^^^^^^^^^^^^^^^^^^^^^^^^^^^^^^^^^^^^^^^^^^^^^^^^^^^^^^^^^^^^^^^^^^^
  File "C:\Users\adnegrau\AppData\Local\Programs\Python\Python312\Lib\site-packages\jupyter_core\utils\__init__.py", line 165, in wrapped
    return loop.run_until_complete(inner)
           ^^^^^^^^^^^^^^^^^^^^^^^^^^^^^^
  File "C:\Users\adnegrau\AppData\Local\Programs\Python\Python312\Lib\asyncio\base_events.py", line 685, in run_until_complete
    return future.result()
           ^^^^^^^^^^^^^^^
  File "C:\Users\adnegrau\AppData\Local\Programs\Python\Python312\Lib\site-packages\nbclient\client.py", line 705, in async_execute
    await self.async_execute_cell(
  File "C:\Users\adnegrau\AppData\Local\Programs\Python\Python312\Lib\site-packages\nbclient\client.py", line 1058, in async_execute_cell
    await self._check_raise_for_error(cell, cell_index, exec_reply)
  File "C:\Users\adnegrau\AppData\Local\Programs\Python\Python312\Lib\site-packages\nbclient\client.py", line 914, in _check_raise_for_error
    raise CellExecutionError.from_cell_and_msg(cell, exec_reply_content)
nbclient.exceptions.CellExecutionError: An error occurred while executing the following cell:
------------------
import mlflow
import openai
import os
import pandas as pd
from getpass import getpass
from azureml.core import Workspace

%reload_ext dotenv
%dotenv

subscription_id = os.environ["subscription_id"]
resource_group_name = os.environ["resource_group_name"]
workspace_name = os.environ["workspace_name"]

aoi_deployment_name = os.environ["AZURE_OPENAI_DEPLOYMENT_NAME"]
azure_openai_key = os.environ["azure_openai_key"]
azure_aoai_endpoint = os.environ["azure_aoai_endpoint"]

os.environ.setdefault("OPENAI_API_KEY", azure_openai_key)
os.environ.setdefault("OPENAI_API_BASE", azure_aoai_endpoint)
os.environ.setdefault("OPENAI_API_VERSION", "2023-05-15")
os.environ.setdefault("OPENAI_API_TYPE", "azure")
os.environ.setdefault("OPENAI_DEPLOYMENT_NAME",aoi_deployment_name)
------------------


[1;31m---------------------------------------------------------------------------[0m
[1;31mModuleNotFoundError[0m                       Traceback (most recent call last)
Cell [1;32mIn[2], line 6[0m
[0;32m      4[0m [38;5;28;01mimport[39;00m [38;5;21;01mpandas[39;00m [38;5;28;01mas[39;00m [38;5;21;01mpd[39;00m
[0;32m      5[0m [38;5;28;01mfrom[39;00m [38;5;21;01mgetpass[39;00m [38;5;28;01mimport[39;00m getpass
[1;32m----> 6[0m [38;5;28;01mfrom[39;00m [38;5;21;01mazureml[39;00m[38;5;21;01m.[39;00m[38;5;21;01mcore[39;00m [38;5;28;01mimport[39;00m Workspace
[0;32m      8[0m get_ipython()[38;5;241m.[39mrun_line_magic([38;5;124m'[39m[38;5;124mreload_ext[39m[38;5;124m'[39m, [38;5;124m'[39m[38;5;124mdotenv[39m[38;5;124m'[39m)
[0;32m      9[0m get_ipython()[38;5;241m.[39mrun_line_magic([38;5;124m'[39m[38;5;124mdotenv[39m[38;5;124m'[39m, [38;5;124m'[39m[38;5;124m'[39m)

[1;31mModuleNotFoundError[0m: No module named 'azureml.core'

