Traceback (most recent call last):
  File "/Users/raouf/handsontest/ai-hands-on-lab/.venv/lib/python3.9/site-packages/jupyter_cache/executors/utils.py", line 58, in single_nb_execution
    executenb(
  File "/Users/raouf/handsontest/ai-hands-on-lab/.venv/lib/python3.9/site-packages/nbclient/client.py", line 1314, in execute
    return NotebookClient(nb=nb, resources=resources, km=km, **kwargs).execute()
  File "/Users/raouf/handsontest/ai-hands-on-lab/.venv/lib/python3.9/site-packages/jupyter_core/utils/__init__.py", line 165, in wrapped
    return loop.run_until_complete(inner)
  File "/Library/Frameworks/Python.framework/Versions/3.9/lib/python3.9/asyncio/base_events.py", line 642, in run_until_complete
    return future.result()
  File "/Users/raouf/handsontest/ai-hands-on-lab/.venv/lib/python3.9/site-packages/nbclient/client.py", line 709, in async_execute
    await self.async_execute_cell(
  File "/Users/raouf/handsontest/ai-hands-on-lab/.venv/lib/python3.9/site-packages/nbclient/client.py", line 1062, in async_execute_cell
    await self._check_raise_for_error(cell, cell_index, exec_reply)
  File "/Users/raouf/handsontest/ai-hands-on-lab/.venv/lib/python3.9/site-packages/nbclient/client.py", line 918, in _check_raise_for_error
    raise CellExecutionError.from_cell_and_msg(cell, exec_reply_content)
nbclient.exceptions.CellExecutionError: An error occurred while executing the following cell:
------------------
query = "Hello"

query_vectors = oai_query_embedding(query)

print(f"The query is: {query}")
print(f"The embedded vector is: {query_vectors}")
print(f"The length of the embedding is: {len(query_vectors)}")
------------------


[0;31m---------------------------------------------------------------------------[0m
[0;31mException[0m                                 Traceback (most recent call last)
Cell [0;32mIn[3], line 3[0m
[1;32m      1[0m query [38;5;241m=[39m [38;5;124m"[39m[38;5;124mHello[39m[38;5;124m"[39m
[0;32m----> 3[0m query_vectors [38;5;241m=[39m [43moai_query_embedding[49m[43m([49m[43mquery[49m[43m)[49m
[1;32m      5[0m [38;5;28mprint[39m([38;5;124mf[39m[38;5;124m"[39m[38;5;124mThe query is: [39m[38;5;132;01m{[39;00mquery[38;5;132;01m}[39;00m[38;5;124m"[39m)
[1;32m      6[0m [38;5;28mprint[39m([38;5;124mf[39m[38;5;124m"[39m[38;5;124mThe embedded vector is: [39m[38;5;132;01m{[39;00mquery_vectors[38;5;132;01m}[39;00m[38;5;124m"[39m)

Cell [0;32mIn[2], line 38[0m, in [0;36moai_query_embedding[0;34m(query, endpoint, api_key, api_version, embedding_model_deployment)[0m
[1;32m     36[0m     [38;5;28;01mreturn[39;00m embeddings_vectors[[38;5;241m0[39m]
[1;32m     37[0m [38;5;28;01melse[39;00m:
[0;32m---> 38[0m     [38;5;28;01mraise[39;00m [38;5;167;01mException[39;00m([38;5;124mf[39m[38;5;124m"[39m[38;5;124mfailed to get embedding: [39m[38;5;132;01m{[39;00membedding_response[38;5;241m.[39mjson()[38;5;132;01m}[39;00m[38;5;124m"[39m)

[0;31mException[0m: failed to get embedding: {'error': {'code': '401', 'message': 'Access denied due to invalid subscription key or wrong API endpoint. Make sure to provide a valid key for an active subscription and use a correct regional API endpoint for your resource.'}}

