Traceback (most recent call last):
  File "c:\Projects\Workshop2024\.venv\Lib\site-packages\jupyter_cache\executors\utils.py", line 58, in single_nb_execution
    executenb(
  File "c:\Projects\Workshop2024\.venv\Lib\site-packages\nbclient\client.py", line 1305, in execute
    return NotebookClient(nb=nb, resources=resources, km=km, **kwargs).execute()
           ^^^^^^^^^^^^^^^^^^^^^^^^^^^^^^^^^^^^^^^^^^^^^^^^^^^^^^^^^^^^^^^^^^^^^
  File "c:\Projects\Workshop2024\.venv\Lib\site-packages\jupyter_core\utils\__init__.py", line 165, in wrapped
    return loop.run_until_complete(inner)
           ^^^^^^^^^^^^^^^^^^^^^^^^^^^^^^
  File "C:\Users\adnegrau\AppData\Local\anaconda3\Lib\asyncio\base_events.py", line 653, in run_until_complete
    return future.result()
           ^^^^^^^^^^^^^^^
  File "c:\Projects\Workshop2024\.venv\Lib\site-packages\nbclient\client.py", line 705, in async_execute
    await self.async_execute_cell(
  File "c:\Projects\Workshop2024\.venv\Lib\site-packages\nbclient\client.py", line 1058, in async_execute_cell
    await self._check_raise_for_error(cell, cell_index, exec_reply)
  File "c:\Projects\Workshop2024\.venv\Lib\site-packages\nbclient\client.py", line 914, in _check_raise_for_error
    raise CellExecutionError.from_cell_and_msg(cell, exec_reply_content)
nbclient.exceptions.CellExecutionError: An error occurred while executing the following cell:
------------------
import pandas as pd
import glob
import os
import openai
import asyncio
import json
import nltk
import tqdm
import backoff
from langchain_community.document_loaders import UnstructuredFileLoader
from langchain.text_splitter import MarkdownHeaderTextSplitter, MarkdownTextSplitter, RecursiveCharacterTextSplitter
from openai import AsyncAzureOpenAI
from typing import Coroutine, Any, Tuple
import plotly.express as px
import tracemalloc

from plotly import colors
from plotly.subplots import make_subplots
import plotly.graph_objects as go 
------------------


[1;31m---------------------------------------------------------------------------[0m
[1;31mModuleNotFoundError[0m                       Traceback (most recent call last)
Cell [1;32mIn[1], line 14[0m
[0;32m     12[0m [38;5;28;01mfrom[39;00m [38;5;21;01mopenai[39;00m [38;5;28;01mimport[39;00m AsyncAzureOpenAI
[0;32m     13[0m [38;5;28;01mfrom[39;00m [38;5;21;01mtyping[39;00m [38;5;28;01mimport[39;00m Coroutine, Any, Tuple
[1;32m---> 14[0m [38;5;28;01mimport[39;00m [38;5;21;01mplotly[39;00m[38;5;21;01m.[39;00m[38;5;21;01mexpress[39;00m [38;5;28;01mas[39;00m [38;5;21;01mpx[39;00m
[0;32m     15[0m [38;5;28;01mimport[39;00m [38;5;21;01mtracemalloc[39;00m
[0;32m     17[0m [38;5;28;01mfrom[39;00m [38;5;21;01mplotly[39;00m [38;5;28;01mimport[39;00m colors

[1;31mModuleNotFoundError[0m: No module named 'plotly'

