Traceback (most recent call last):
  File "C:\Users\adnegrau\AppData\Local\Programs\Python\Python312\Lib\site-packages\jupyter_cache\executors\utils.py", line 58, in single_nb_execution
    executenb(
  File "C:\Users\adnegrau\AppData\Local\Programs\Python\Python312\Lib\site-packages\nbclient\client.py", line 1305, in execute
    return NotebookClient(nb=nb, resources=resources, km=km, **kwargs).execute()
           ^^^^^^^^^^^^^^^^^^^^^^^^^^^^^^^^^^^^^^^^^^^^^^^^^^^^^^^^^^^^^^^^^^^^^
  File "C:\Users\adnegrau\AppData\Local\Programs\Python\Python312\Lib\site-packages\jupyter_core\utils\__init__.py", line 165, in wrapped
    return loop.run_until_complete(inner)
           ^^^^^^^^^^^^^^^^^^^^^^^^^^^^^^
  File "C:\Users\adnegrau\AppData\Local\Programs\Python\Python312\Lib\asyncio\base_events.py", line 685, in run_until_complete
    return future.result()
           ^^^^^^^^^^^^^^^
  File "C:\Users\adnegrau\AppData\Local\Programs\Python\Python312\Lib\site-packages\nbclient\client.py", line 705, in async_execute
    await self.async_execute_cell(
  File "C:\Users\adnegrau\AppData\Local\Programs\Python\Python312\Lib\site-packages\nbclient\client.py", line 1058, in async_execute_cell
    await self._check_raise_for_error(cell, cell_index, exec_reply)
  File "C:\Users\adnegrau\AppData\Local\Programs\Python\Python312\Lib\site-packages\nbclient\client.py", line 914, in _check_raise_for_error
    raise CellExecutionError.from_cell_and_msg(cell, exec_reply_content)
nbclient.exceptions.CellExecutionError: An error occurred while executing the following cell:
------------------
import numpy as np
import pandas as pd
from tqdm import tqdm
from spacy.lang.en.stop_words import STOP_WORDS

import en_core_web_sm
from sklearn.cluster import KMeans
from sklearn.feature_extraction.text import TfidfVectorizer
from sklearn.decomposition import PCA
from sklearn.manifold import TSNE
from sklearn.decomposition import LatentDirichletAllocation
from sklearn.feature_extraction.text import CountVectorizer

import matplotlib.pyplot as plt

plt.style.use("ggplot")
pd.set_option("display.max_colwidth", None)
------------------


[1;31m---------------------------------------------------------------------------[0m
[1;31mModuleNotFoundError[0m                       Traceback (most recent call last)
Cell [1;32mIn[2], line 4[0m
[0;32m      2[0m [38;5;28;01mimport[39;00m [38;5;21;01mpandas[39;00m [38;5;28;01mas[39;00m [38;5;21;01mpd[39;00m
[0;32m      3[0m [38;5;28;01mfrom[39;00m [38;5;21;01mtqdm[39;00m [38;5;28;01mimport[39;00m tqdm
[1;32m----> 4[0m [38;5;28;01mfrom[39;00m [38;5;21;01mspacy[39;00m[38;5;21;01m.[39;00m[38;5;21;01mlang[39;00m[38;5;21;01m.[39;00m[38;5;21;01men[39;00m[38;5;21;01m.[39;00m[38;5;21;01mstop_words[39;00m [38;5;28;01mimport[39;00m STOP_WORDS
[0;32m      6[0m [38;5;28;01mimport[39;00m [38;5;21;01men_core_web_sm[39;00m
[0;32m      7[0m [38;5;28;01mfrom[39;00m [38;5;21;01msklearn[39;00m[38;5;21;01m.[39;00m[38;5;21;01mcluster[39;00m [38;5;28;01mimport[39;00m KMeans

[1;31mModuleNotFoundError[0m: No module named 'spacy'

